<robot name="magician">

    <!-- Defining the colors used in this robot -->
    <material name="Black">
        <color rgba="0 0 0 1"/>
    </material>

    <material name="White">
        <color rgba="1 1 1 1"/>
    </material>

    <material name="Grey">
        <color rgba="0.9 0.9 0.9 1"/>
    </material>

    <!--  -->
    <link name="base_link">
        <visual>
            <origin xyz="0 0 0" rpy="0 0 0"/>
            <geometry>
                <mesh filename="package://magician/meshes/base_link.STL"/>
            </geometry>
            <material name="White"/>
        </visual>
        <collision>
            <origin xyz="0 0 0" rpy="0 0 0"/>
            <geometry>
                <mesh filename="package://magician/meshes/base_link.STL"/>
            </geometry>
        </collision>
    </link>

    <joint name="joint_1" type ="revolute">
        <origin xyz="0 0 0.024" rpy="0 0 0"/>
        <parent link="base_link"/>
        <child link="link_1"/>
        <axis xyz="0 0 1"/>
        <limit effort="150.0" lower="-3.14159265" upper="3.14159265" velocity="3.15"/>
    </joint>

    <link name="link_1">
        <visual>
            <origin xyz="0 0 0" rpy="0 0 0"/>
            <geometry>
                <mesh filename="package://magician/meshes/link_1.dae"/>
            </geometry>
        </visual>
        <collision>
            <origin xyz="0 0 0" rpy="0 0 0"/>
            <geometry>
                <mesh filename="package://magician/meshes/link_1.STL"/>
            </geometry>
        </collision>
    </link>

    
    <joint name="joint_2" type="revolute">
        <origin xyz="-0.01175 0 0.114" rpy="1.570796325 0 -1.570796325"/>
        <parent link="link_1"/>
        <child link="link_2"/>
        <axis xyz="0 0 1"/>
        <limit effort="150.0" lower="0" upper="1.570796325" velocity="3.15"/>
    </joint>

    <link name="link_2">
        <visual>
            <origin xyz="0 0 0" rpy="0 0 0"/>
            <geometry>
                <mesh filename="package://magician/meshes/link_2.dae"/>
            </geometry>
        </visual>
        <collision>
            <origin xyz="0 0 0" rpy="0 0 0"/>
            <geometry>
                <mesh filename="package://magician/meshes/link_2.STL"/>
            </geometry>
        </collision>
    </link>

    <joint name="joint_5" type ="revolute">
        <origin xyz="0.02699 0.13228 -0.01175" rpy="0 3.14159265 0"/>
        <parent link="link_2"/>
        <child link="link_5"/>
        <axis xyz="0 0 1"/>
        <limit effort="150.0" lower="0" upper="1.570796325" velocity="3.15"/>
    </joint>

    <link name="link_5">
        <visual>
            <origin xyz="0 0 0" rpy="0 0 0"/>
            <geometry>
                <mesh filename="package://magician/meshes/link_5.dae"/>
            </geometry>
        </visual>
        <collision>
            <origin xyz="0 0 0" rpy="0 0 0"/>
            <geometry>
                <mesh filename="package://magician/meshes/link_5.STL"/>
            </geometry>
        </collision>
    </link>

    <joint name="joint_6" type ="revolute">
        <origin xyz="0.07431 -0.12684 0.0" rpy="0 3.14159265 0"/>
        <parent link="link_5"/>
        <child link="link_6"/>
        <axis xyz="0 0 1"/>
        <limit effort="150.0" lower="-3.14159265" upper="3.14159265" velocity="3.15"/>

    </joint>

    <link name="link_6">
        <visual>
            <origin xyz="0 0 0" rpy="0 0 0"/>
            <geometry>
                <mesh filename="package://magician/meshes/link_6.STL"/>
            </geometry>
        </visual>
        <collision>
            <origin xyz="0 0 0" rpy="0 0 0"/>
            <geometry>
                <mesh filename="package://magician/meshes/link_6.STL"/>
            </geometry>
        </collision>
    </link>

    <joint name="joint_pen" type ="fixed">
        <origin xyz="-0.06 0.0 0" rpy="-1.570796325 -1.570796325 0"/>
        <parent link="link_6"/>
        <child link="link_pen"/>
        <axis xyz="0 0 1"/>
        <limit effort="150.0" lower="0" upper="1.570796325" velocity="3.15"/>
    </joint>

    <link name="link_pen">
        <visual>
            <origin xyz="0 0 0" rpy="0 0 0"/>
            <geometry>
                <mesh filename="package://magician/meshes/bi.dae"/>
            </geometry>
        </visual>
    </link>

    <joint name="joint_pen_end" type ="fixed">
        <origin xyz="0 0.0 -0.098" rpy="0 0 0"/>
        <parent link="link_pen"/>
        <child link="end_link"/>
        <axis xyz="0 0 1"/>
        <limit effort="150.0" lower="0" upper="1.570796325" velocity="3.15"/>
    </joint>

    <link name="end_link">
    </link>

</robot>  
